Process Process-44:
Traceback (most recent call last):
  File "/home/cs/guretss/conda/my_sagemath_env/envs/sagemath/lib/python3.12/multiprocessing/process.py", line 314, in _bootstrap
    self.run()
  File "/home/cs/guretss/conda/my_sagemath_env/envs/sagemath/lib/python3.12/multiprocessing/process.py", line 108, in run
    self._target(*self._args, **self._kwargs)
  File "/home/cs/guretss/sage/SageTest.py", line 16, in read_and_process
    G = Graph(graph, multiedges=False, loops=False)
        ^^^^^^^^^^^^^^^^^^^^^^^^^^^^^^^^^^^^^^^^^^^
  File "/home/cs/guretss/conda/my_sagemath_env/envs/sagemath/lib/python3.12/site-packages/sage/graphs/graph.py", line 1205, in __init__
    from_networkx_graph(self, data,
  File "/home/cs/guretss/conda/my_sagemath_env/envs/sagemath/lib/python3.12/site-packages/sage/graphs/graph_input.py", line 799, in from_networkx_graph
    G.add_edges((u, v, r(ll)) for u, v, ll in gnx.edges(data=True))
  File "/home/cs/guretss/conda/my_sagemath_env/envs/sagemath/lib/python3.12/site-packages/sage/graphs/generic_graph.py", line 12368, in add_edges
    self._backend.add_edges(edges, self._directed, remove_loops=not loops)
  File "sage/graphs/base/c_graph.pyx", line 2358, in sage.graphs.base.c_graph.CGraphBackend.add_edges (build/cythonized/sage/graphs/base/c_graph.cpp:31891)
    self.add_edge(u, v, l, directed)
  File "sage/graphs/base/c_graph.pyx", line 2449, in sage.graphs.base.c_graph.CGraphBackend.add_edge (build/cythonized/sage/graphs/base/c_graph.cpp:32273)
    raise ValueError(f"cannot add edge from {u!r} to {v!r} in graph without loops")
ValueError: cannot add edge from '95' to '95' in graph without loops
